nohup: ignoring input
/remote-home/zzq/.conda/envs/nvf/lib/python3.10/site-packages/tyro/_fields.py:1066: UserWarning: Mutable type <class 'config.EnvConfig'> is used as a default value for `env`. This is dangerous! Consider using `dataclasses.field(default_factory=...)` or marking <class 'config.EnvConfig'> as frozen.
  warnings.warn(
Warning:
Unable to load the following plugins:

	libio_e57.so: libio_e57.so does not seem to be a Qt Plugin.

Cannot load library /remote-home/zzq/.conda/envs/nvf/lib/python3.10/site-packages/pymeshlab/lib/plugins/libio_e57.so: (/lib/x86_64-linux-gnu/libp11-kit.so.0: undefined symbol: ffi_type_pointer, version LIBFFI_BASE_7.0)

  0%|          | 0/64 [00:00<?, ?it/s]  8%|▊         | 5/64 [00:00<00:01, 49.34it/s] 17%|█▋        | 11/64 [00:00<00:00, 53.09it/s] 27%|██▋       | 17/64 [00:00<00:00, 53.60it/s] 36%|███▌      | 23/64 [00:00<00:00, 48.93it/s] 47%|████▋     | 30/64 [00:00<00:00, 53.82it/s] 62%|██████▎   | 40/64 [00:00<00:00, 67.10it/s] 73%|███████▎  | 47/64 [00:00<00:00, 66.39it/s] 84%|████████▍ | 54/64 [00:00<00:00, 61.95it/s] 97%|█████████▋| 62/64 [00:01<00:00, 66.02it/s]100%|██████████| 64/64 [00:01<00:00, 60.69it/s]
dealing with policy_1 uncertainty
[41, 28]
[41, 28, 51]
[41, 28, 51, 34]
[41, 28, 51, 34, 26]
[41, 28, 51, 34, 26, 2]
[41, 28, 51, 34, 26, 2, 6]
[41, 28, 51, 34, 26, 2, 6, 1]
[41, 28, 51, 34, 26, 2, 6, 1, 5]
[41, 28, 51, 34, 26, 2, 6, 1, 5, 7]
[41, 28, 51, 34, 26, 2, 6, 1, 5, 7, 4]
[41, 28, 51, 34, 26, 2, 6, 1, 5, 7, 4, 0]
[41, 28, 51, 34, 26, 2, 6, 1, 5, 7, 4, 0, 3]
[41, 28, 51, 34, 26, 2, 6, 1, 5, 7, 4, 0, 3, 8]
[41, 28, 51, 34, 26, 2, 6, 1, 5, 7, 4, 0, 3, 8, 15]
[41, 28, 51, 34, 26, 2, 6, 1, 5, 7, 4, 0, 3, 8, 15, 10]
[41, 28, 51, 34, 26, 2, 6, 1, 5, 7, 4, 0, 3, 8, 15, 10, 14]
[41, 28, 51, 34, 26, 2, 6, 1, 5, 7, 4, 0, 3, 8, 15, 10, 14, 9]
[41, 28, 51, 34, 26, 2, 6, 1, 5, 7, 4, 0, 3, 8, 15, 10, 14, 9, 12]
[41, 28, 51, 34, 26, 2, 6, 1, 5, 7, 4, 0, 3, 8, 15, 10, 14, 9, 12, 13]
[41, 28, 51, 34, 26, 2, 6, 1, 5, 7, 4, 0, 3, 8, 15, 10, 14, 9, 12, 13, 11]
CUDA
Generating data for init
/remote-home/zzq/.conda/envs/nvf/lib/python3.10/site-packages/boxx/ylcompat.py:69: BoxxWarning: warning from boxx
    os.environ["DISPLAY"] is not found
    plt.show() are redirect to plt.savefig(tmp)
    function: show, loga, crun, heatmap, plot will be affected
  def __setDisplayEnv():
saving data to data/shapenet/init/transforms.json
Starts extracting mesh
Ends extracting mesh
Generating data for eval
saving data to data/shapenet/eval/transforms.json
[16:22:05] Saving checkpoints to: cfg/config/dataset/instant-ngp/latest_checkpoint/nerfstudio_models      trainer.py:142
╭─────────────────────────────────────────── Viewer ───────────────────────────────────────────╮
│        ╷                                                                                     │
│   HTTP │ https://viewer.nerf.studio/versions/23-05-15-1/?websocket_url=ws://localhost:7007   │
│        ╵                                                                                     │
╰──────────────────────────────────────────────────────────────────────────────────────────────╯
[NOTE] Not running eval iterations since only viewer is enabled.
Use --vis {wandb, tensorboard, viewer+wandb, viewer+tensorboard} to run with eval.
No Nerfstudio checkpoint to load, so training from scratch.
Disabled tensorboard/wandb event writers
entropy use uniform sampler: False
policy_1 uncertainty already finished 
dealing with policy_1 PSNR
[0, 31]
[0, 31, 3]
[0, 31, 3, 6]
[0, 31, 3, 6, 24]
[0, 31, 3, 6, 24, 32]
[0, 31, 3, 6, 24, 32, 55]
[0, 31, 3, 6, 24, 32, 55, 62]
[0, 31, 3, 6, 24, 32, 55, 62, 58]
[0, 31, 3, 6, 24, 32, 55, 62, 58, 61]
[0, 31, 3, 6, 24, 32, 55, 62, 58, 61, 57]
[0, 31, 3, 6, 24, 32, 55, 62, 58, 61, 57, 39]
[0, 31, 3, 6, 24, 32, 55, 62, 58, 61, 57, 39, 54]
[0, 31, 3, 6, 24, 32, 55, 62, 58, 61, 57, 39, 54, 49]
[0, 31, 3, 6, 24, 32, 55, 62, 58, 61, 57, 39, 54, 49, 48]
[0, 31, 3, 6, 24, 32, 55, 62, 58, 61, 57, 39, 54, 49, 48, 50]
[0, 31, 3, 6, 24, 32, 55, 62, 58, 61, 57, 39, 54, 49, 48, 50, 59]
[0, 31, 3, 6, 24, 32, 55, 62, 58, 61, 57, 39, 54, 49, 48, 50, 59, 60]
[0, 31, 3, 6, 24, 32, 55, 62, 58, 61, 57, 39, 54, 49, 48, 50, 59, 60, 63]
[0, 31, 3, 6, 24, 32, 55, 62, 58, 61, 57, 39, 54, 49, 48, 50, 59, 60, 63, 56]
[0, 31, 3, 6, 24, 32, 55, 62, 58, 61, 57, 39, 54, 49, 48, 50, 59, 60, 63, 56, 53]
CUDA
Generating data for init
saving data to data/shapenet/init/transforms.json
Starts extracting mesh
Ends extracting mesh
Generating data for eval
Invalid value in CUDA queue enqueue (integrator_reset adaptive_sampling_convergence_check)

Refer to the Cycles GPU rendering documentation for possible solutions:
https://docs.blender.org/manual/en/latest/render/cycles/gpu_rendering.html

Traceback (most recent call last):
  File "/attached/data/remote-home2/zzq/04-fep-nbv/fep_nbv/test/policy_test.py", line 222, in <module>
    tracker = RefMetricTracker(cfg, env=env)
  File "/attached/data/remote-home2/zzq/04-fep-nbv/nvf/metric/MetricTracker.py", line 37, in __init__
    np_images, transforms = self.env.get_images(mode='eval',return_quat=False)
  File "/attached/data/remote-home2/zzq/04-fep-nbv/fep_nbv/env/shapenet_env.py", line 129, in get_images
    return self.gen_data(mode, return_quat=return_quat)
  File "/attached/data/remote-home2/zzq/04-fep-nbv/fep_nbv/env/shapenet_env.py", line 150, in gen_data
    image = self.scene.render_pose(pose)
  File "/attached/data/remote-home2/zzq/04-fep-nbv/fep_nbv/env/shapenet_scene.py", line 215, in render_pose
    result = self.render() #
  File "/attached/data/remote-home2/zzq/04-fep-nbv/fep_nbv/env/shapenet_scene.py", line 566, in render
    return super().render()
  File "/attached/data/remote-home2/zzq/04-fep-nbv/fep_nbv/env/shapenet_scene.py", line 422, in render
    result = bpycv.render_data()
  File "/remote-home/zzq/.conda/envs/nvf/lib/python3.10/site-packages/bpycv/render_utils.py", line 115, in render_data
    render_result["image"] = _render_image()
  File "/remote-home/zzq/.conda/envs/nvf/lib/python3.10/site-packages/bpycv/render_utils.py", line 94, in render_image
    bpy.ops.render.render(write_still=True)
  File "/remote-home/zzq/.conda/envs/nvf/lib/python3.10/site-packages/bpy/3.6/scripts/modules/bpy/ops.py", line 113, in __call__
    ret = _op_call(self.idname_py(), None, kw)
RuntimeError: Error: Invalid value in CUDA queue enqueue (integrator_reset adaptive_sampling_convergence_check)
Error: Invalid value in CUDA queue enqueue (integrator_reset adaptive_sampling_convergence_check)

